<?xml version="1.0" encoding="UTF-8"?>
<!-- Generated by org.testng.reporters.JUnitXMLReporter -->
<testsuite ignored="0" hostname="WINDOWS-BR9DI0P" failures="2" tests="15" name="edgeTest" time="120.731" errors="0" timestamp="2025-05-26T19:50:02 CDT">
  <testcase classname="testCases.TC01_LaunchApplication" name="testLaunchApplication" time="0.288"/>
  <testcase classname="testCases.TC03_AddToCart" name="testAddToCart" time="3.092">
    <skipped/>
  </testcase> <!-- testAddToCart -->
  <testcase classname="testCases.TC03_AddToCart" name="testAddToCart" time="6.325"/>
  <testcase classname="testCases.TC05_AddToWishList" name="testAddToWishList" time="13.629">
    <skipped/>
  </testcase> <!-- testAddToWishList -->
  <testcase classname="testCases.TC05_AddToWishList" name="testAddToWishList" time="10.348">
    <skipped/>
  </testcase> <!-- testAddToWishList -->
  <testcase classname="testCases.TC05_AddToWishList" name="testAddToWishList" time="10.282">
    <failure type="java.lang.AssertionError" message="Test failed due to unexpected exception.">
      <![CDATA[java.lang.AssertionError: Test failed due to unexpected exception.
at testCases.TC05_AddToWishList.testAddToWishList(TC05_AddToWishList.java:77)
at java.base/java.util.ArrayList.forEach(ArrayList.java:1596)
at java.base/java.util.concurrent.FutureTask.run(FutureTask.java:317)
at java.base/java.util.concurrent.ThreadPoolExecutor.runWorker(ThreadPoolExecutor.java:1144)
at java.base/java.util.concurrent.ThreadPoolExecutor$Worker.run(ThreadPoolExecutor.java:642)
at java.base/java.lang.Thread.run(Thread.java:1583)
... Removed 16 stack frames]]>
    </failure>
  </testcase> <!-- testAddToWishList -->
  <testcase classname="testCases.TC06_AddAffiliate" name="testAddAffiliate" time="5.647"/>
  <testcase classname="testCases.TC02_Login" name="testLogin" time="2.273"/>
  <testcase classname="testCases.TC02_Login" name="testLogin" time="3.121"/>
  <testcase classname="testCases.TC02_Login" name="testLogin" time="3.238"/>
  <testcase classname="testCases.TC02_Login" name="testLogin" time="2.234"/>
  <testcase classname="testCases.TC02_Login" name="testLogin" time="1.555"/>
  <testcase classname="testCases.TC04_CompletePurchase" name="testCompletePurchase" time="3.607">
    <skipped/>
  </testcase> <!-- testCompletePurchase -->
  <testcase classname="testCases.TC04_CompletePurchase" name="testCompletePurchase" time="5.558">
    <skipped/>
  </testcase> <!-- testCompletePurchase -->
  <testcase classname="testCases.TC04_CompletePurchase" name="testCompletePurchase" time="11.683">
    <failure type="java.lang.AssertionError" message="Test failed due to unexpected exception.">
      <![CDATA[java.lang.AssertionError: Test failed due to unexpected exception.
at testCases.TC04_CompletePurchase.testCompletePurchase(TC04_CompletePurchase.java:81)
at java.base/java.util.ArrayList.forEach(ArrayList.java:1596)
at java.base/java.util.concurrent.FutureTask.run(FutureTask.java:317)
at java.base/java.util.concurrent.ThreadPoolExecutor.runWorker(ThreadPoolExecutor.java:1144)
at java.base/java.util.concurrent.ThreadPoolExecutor$Worker.run(ThreadPoolExecutor.java:642)
at java.base/java.lang.Thread.run(Thread.java:1583)
... Removed 16 stack frames]]>
    </failure>
  </testcase> <!-- testCompletePurchase -->
</testsuite> <!-- edgeTest -->
